Workbook

Sheet TongQuan
A1: KẾ HOẠCH THI CÔNG TỔNG THỂ – BÁO CÁO LÃNH ĐẠO
A2: Dự án: Nhà máy sản xuất các sản phẩm sau thép | Tổng hợp từ Tổng tiến độ Rev 01 (29/06/2026) và bảng khối lượng Prelim Rev 00
A3: 1. THÔNG TIN CHUNG
A4: Dự án | C4: Nhà máy sản xuất các sản phẩm sau thép
A5: Khách hàng / CĐT (theo logo trên bảng tiến độ) | C5: Tôn Đông Á
A6: Nhà thầu lập tiến độ | C6: AZB (Build Trust on Discipline)
A7: Gói thầu (theo tên file bảng khối lượng) | C7: Gói C, D
A8: Hạng mục chính | C8: Nhà xưởng CM5–CM7, kho thành phẩm, kho bán thành phẩm; nhà văn phòng 2 tầng; nhà đóng container; cầu ống; trạm cân; nhà bảo vệ & hàng rào; cột cờ; cổng & bảng hiệu; hạ tầng (thoát nước mưa/thải, đường nội bộ, bó vỉa, cấp nước)
A9: Tài liệu gốc | C9: Tổng tiến độ thi công phối hợp Rev 01 (29/06/2026); TON_DONG_A_Goi_C_D_PCCC-PRELIM_AZB Rev 00
A11: 2. CHỈ SỐ CHÍNH (công thức liên kết các sheet)
A12: Ngày báo cáo | C12: =TienDo!$D$3 -> 46299 | D12: Sửa tại TienDo!D3
A13: Ngày bắt đầu (sớm nhất) | C13: =MIN(TienDo!$F$8:$F$92) -> 46194 | D13: ID 1
A14: Ngày hoàn thành (muộn nhất) | C14: =MAX(TienDo!$G$8:$G$92) -> 46464 | D14: ID 1, 84, 85
A15: Tổng thời gian (ngày lịch) | C15: =MAX(TienDo!$G$8:$G$92)-MIN(TienDo!$F$8:$F$92) -> 270 | D15: Chưa tách Chủ nhật/lễ/Tết (RuiRo #6)
A16: % thời gian dự án đã trôi qua theo lịch | C16: =MAX(0,MIN(1,(TienDo!$D$3-MIN(TienDo!$F$8:$F$92))/(MAX(TienDo!$G$8:$G$92)-MIN(TienDo!$F$8:$F$92)))) -> 0.38888889 | D16: Tại ngày báo cáo
A17: Số dòng trong WBS | C17: =COUNTA(TienDo!$A$8:$A$92) -> 85 | D17: Gồm nhóm tổng hợp
A18: Số công việc chi tiết | C18: =COUNTIF(TienDo!$D$8:$D$92,"Chi tiết") -> 57
A19: Công việc chi tiết đang thi công theo KH | C19: =COUNTIFS(TienDo!$D$8:$D$92,"Chi tiết",TienDo!$K$8:$K$92,"Đang thi công") -> 16 | D19: Theo kế hoạch, chưa phải thực tế
A20: Công việc chi tiết đã đến hạn xong theo KH | C20: =COUNTIFS(TienDo!$D$8:$D$92,"Chi tiết",TienDo!$K$8:$K$92,"Đến hạn xong") -> 16 | D20: Theo kế hoạch, cần đối chiếu thực tế
A21: Dòng có số ngày lệch với ngày tháng | C21: =COUNTIF(TienDo!$I$8:$I$92,"Lệch") -> 1 | D21: ID 8 (RuiRo #3)
A22: Công việc chi tiết giao kỳ nghỉ Tết (giả định) | C22: =COUNTIF(TienDo!$L$8:$L$92,"Có") -> 6 | D22: Xem TienDo cột L
A23: Ban chỉ huy (người) | C23: =NguonLuc!$C$18 -> 13 | D23: NguonLuc
A24: Công nhân cao điểm (người) | C24: =HSSE!$C$6 -> 250 | D24: HSSE
A25: Tổng chi phí phục vụ thi công – Prelim (VND, chưa VAT) | C25: =ChiPhi!$F$5 -> 1.5470112e+10 | D25: ChiPhi
A26: Prelim / giá trị hợp đồng 192 tỷ | C26: =ChiPhi!$F$87 -> 0.080573499 | D26: Hoặc 5,53% nếu 280 tỷ (RuiRo #13)
A27: Số kiến nghị/rủi ro mức Cao | C27: =RuiRo!$C$22 -> 8 | D27: Xem sheet RuiRo
A29: 3. CÁC MỐC CHÍNH & DỰ TRỮ THỜI GIAN SO VỚI MỐC CUỐI
A30: ID | B30: Mốc | C30: Ngày | D30: Còn lại (+) / đã qua (–) so với ngày BC (ngày) | E30: Dự trữ so với mốc cuối (ngày) | F30: Trạng thái theo KH | G30: Ghi chú
A31: 1 | B31: Khởi công / bắt đầu công tác chuẩn bị | C31: =TienDo!$F$8 -> 46194 | D31: =C31-TienDo!$D$3 -> -105 | E31: =MAX(TienDo!$G$8:$G$92)-C31 -> 270 | F31: =IF(C31<TienDo!$D$3,"Đến hạn theo KH","Sắp tới") -> Đến hạn theo KH
A32: 3 | B32: Bắt đầu ép cọc đại trà | C32: =TienDo!$F$10 -> 46218 | D32: =C32-TienDo!$D$3 -> -81 | E32: =MAX(TienDo!$G$8:$G$92)-C32 -> 246 | F32: =IF(C32<TienDo!$D$3,"Đến hạn theo KH","Sắp tới") -> Đến hạn theo KH
A33: 4 | B33: Hoàn thành ép cọc nhà Văn phòng | C33: =TienDo!$G$11 -> 46233 | D33: =C33-TienDo!$D$3 -> -66 | E33: =MAX(TienDo!$G$8:$G$92)-C33 -> 231 | F33: =IF(C33<TienDo!$D$3,"Đến hạn theo KH","Sắp tới") -> Đến hạn theo KH
A34: 3 | B34: Hoàn thành ép cọc nhà Xưởng | C34: =TienDo!$G$10 -> 46268 | D34: =C34-TienDo!$D$3 -> -31 | E34: =MAX(TienDo!$G$8:$G$92)-C34 -> 196 | F34: =IF(C34<TienDo!$D$3,"Đến hạn theo KH","Sắp tới") -> Đến hạn theo KH | G34: Móng xưởng đã chạy từ 25/07
A35: 19 | B35: Hoàn thành dựng kết cấu thép nhà Văn phòng | C35: =TienDo!$G$26 -> 46270 | D35: =C35-TienDo!$D$3 -> -29 | E35: =MAX(TienDo!$G$8:$G$92)-C35 -> 194 | F35: =IF(C35<TienDo!$D$3,"Đến hạn theo KH","Sắp tới") -> Đến hạn theo KH
A36: 5 | B36: Hoàn thành ép cọc hạng mục phụ trợ | C36: =TienDo!$G$12 -> 46278 | D36: =C36-TienDo!$D$3 -> -21 | E36: =MAX(TienDo!$G$8:$G$92)-C36 -> 186 | F36: =IF(C36<TienDo!$D$3,"Đến hạn theo KH","Sắp tới") -> Đến hạn theo KH
A37: 36 | B37: Hoàn thành móng, cổ cột, đà kiềng nhà Xưởng | C37: =TienDo!$G$43 -> 46280 | D37: =C37-TienDo!$D$3 -> -19 | E37: =MAX(TienDo!$G$8:$G$92)-C37 -> 184 | F37: =IF(C37<TienDo!$D$3,"Đến hạn theo KH","Sắp tới") -> Đến hạn theo KH
A38: 80 | B38: Hoàn thành trạm cân | C38: =TienDo!$G$87 -> 46293 | D38: =C38-TienDo!$D$3 -> -6 | E38: =MAX(TienDo!$G$8:$G$92)-C38 -> 171 | F38: =IF(C38<TienDo!$D$3,"Đến hạn theo KH","Sắp tới") -> Đến hạn theo KH
A39: 77 | B39: Hoàn thành cầu ống | C39: =TienDo!$G$84 -> 46310 | D39: =C39-TienDo!$D$3 -> 11 | E39: =MAX(TienDo!$G$8:$G$92)-C39 -> 154 | F39: =IF(C39<TienDo!$D$3,"Đến hạn theo KH","Sắp tới") -> Sắp tới
A40: 57 | B40: Hoàn thành nhà đóng container | C40: =TienDo!$G$64 -> 46344 | D40: =C40-TienDo!$D$3 -> 45 | E40: =MAX(TienDo!$G$8:$G$92)-C40 -> 120 | F40: =IF(C40<TienDo!$D$3,"Đến hạn theo KH","Sắp tới") -> Sắp tới
A41: 25 | B41: Bàn giao nhà Văn phòng | C41: =TienDo!$G$32 -> 46360 | D41: =C41-TienDo!$D$3 -> 61 | E41: =MAX(TienDo!$G$8:$G$92)-C41 -> 104 | F41: =IF(C41<TienDo!$D$3,"Đến hạn theo KH","Sắp tới") -> Sắp tới
A42: 45 | B42: Hoàn thành đổ bê tông sàn nền nhà Xưởng | C42: =TienDo!$G$52 -> 46372 | D42: =C42-TienDo!$D$3 -> 73 | E42: =MAX(TienDo!$G$8:$G$92)-C42 -> 92 | F42: =IF(C42<TienDo!$D$3,"Đến hạn theo KH","Sắp tới") -> Sắp tới
...

Sheet TienDo
A1: KẾ HOẠCH THI CÔNG CHI TIẾT – GANTT (WBS 85 CÔNG VIỆC)
A2: Dự án: Nhà máy sản xuất các sản phẩm sau thép | Nguồn: Tổng tiến độ thi công phối hợp Rev 01 (29/06/2026) – ngày tính theo ngày lịch
C3: Ngày báo cáo (sửa khi cập nhật): | D3: 46299
C4: Giả định nghỉ Tết Đinh Mùi 2027 (từ – đến; Mùng 1 = 06/02/2027, cần theo lịch nghỉ chính thức): | F4: 46422 | G4: 46432
C5: Chú giải Gantt: xanh đậm = nhóm tổng hợp | xanh = công việc | cam = dự trữ ≤ 30 ngày so với mốc cuối | đỏ = dự trữ 0 (gần găng) | cột đỏ nhạt = tuần chứa ngày báo cáo. Dự trữ tính theo ngày tháng (mốc cuối – ngày kết thúc), không phải total float của MS Project.
A6: ID | B6: Nhóm hạng mục | C6: Hạng mục / công việc | D6: Loại | E6: Số ngày (MSP) | F6: Bắt đầu | G6: Kết thúc | H6: Số ngày (tính lại) | I6: Kiểm tra | J6: % theo KH tại ngày BC | K6: Trạng thái theo KH | L6: Giao Tết | M6: Dự trữ vs mốc cuối (ngày) | N6: Ghi chú | O6: 06/2026 | R6: 07/2026 | V6: 08/2026 | AA6: 09/2026 | AE6: 10/2026 | AI6: 11/2026 | AN6: 12/2026 | AR6: 01/2027 | AV6: 02/2027 | AZ6: 03/2027
O7: 46188 | P7: =O7+7 -> 46195 | Q7: =P7+7 -> 46202 | R7: =Q7+7 -> 46209 | S7: =R7+7 -> 46216 | T7: =S7+7 -> 46223 | U7: =T7+7 -> 46230 | V7: =U7+7 -> 46237 | W7: =V7+7 -> 46244 | ... BB7: =BA7+7 -> 46461
A8: 1 | B8: Tổng hợp | C8: TỔNG TIẾN ĐỘ THI CÔNG - 270 NGÀY | D8: Tổng hợp | E8: 270 | F8: 46194 | G8: 46464 | H8: =G8-F8 -> 270 | I8: =IF(ABS(H8-E8)<1,"OK","Lệch") -> OK | J8: =MAX(0,MIN(1,($D$3-F8)/(G8-F8))) -> 0.38888889 | K8: =IF($D$3<F8,"Chưa bắt đầu",IF($D$3>G8,"Đến hạn xong","Đang thi công")) -> Đang thi công | L8: =IF(AND(D8="Chi tiết",F8<=$G$4,G8>=$F$4),"Có","") | M8: =MAX($G$8:$G$92)-G8 -> 0
A9: 2 | B9: Ép cọc | C9: I. TIẾN ĐỘ BÀN GIAO CỌC ÉP | D9: Tổng hợp | E9: 60 | F9: 46218 | G9: 46278 | H9: =G9-F9 -> 60 | I9: =IF(ABS(H9-E9)<1,"OK","Lệch") -> OK | J9: =MAX(0,MIN(1,($D$3-F9)/(G9-F9))) -> 1 | K9: =IF($D$3<F9,"Chưa bắt đầu",IF($D$3>G9,"Đến hạn xong","Đang thi công")) -> Đến hạn xong | L9: =IF(AND(D9="Chi tiết",F9<=$G$4,G9>=$F$4),"Có","") | M9: =MAX($G$8:$G$92)-G9 -> 186 | N9: Mốc bàn giao cọc ép là điều kiện đầu vào cho móng các nhà – cần theo dõi phối hợp (RuiRo #5).
A10: 3 | B10: Ép cọc | C10: Ép cọc đại trà nhà Xưởng (ép từ trục 1 đến 42) | D10: Chi tiết | E10: 50 | F10: 46218 | G10: 46268 | H10: =G10-F10 -> 50 | I10: =IF(ABS(H10-E10)<1,"OK","Lệch") -> OK | J10: =MAX(0,MIN(1,($D$3-F10)/(G10-F10))) -> 1 | K10: =IF($D$3<F10,"Chưa bắt đầu",IF($D$3>G10,"Đến hạn xong","Đang thi công")) -> Đến hạn xong | L10: =IF(AND(D10="Chi tiết",F10<=$G$4,G10>=$F$4),"Có","") | M10: =MAX($G$8:$G$92)-G10 -> 196
A11: 4 | B11: Ép cọc | C11: Ép cọc đại trà nhà Văn Phòng | D11: Chi tiết | E11: 15 | F11: 46218 | G11: 46233 | H11: =G11-F11 -> 15 | I11: =IF(ABS(H11-E11)<1,"OK","Lệch") -> OK | J11: =MAX(0,MIN(1,($D$3-F11)/(G11-F11))) -> 1 | K11: =IF($D$3<F11,"Chưa bắt đầu",IF($D$3>G11,"Đến hạn xong","Đang thi công")) -> Đến hạn xong | L11: =IF(AND(D11="Chi tiết",F11<=$G$4,G11>=$F$4),"Có","") | M11: =MAX($G$8:$G$92)-G11 -> 231
A12: 5 | B12: Ép cọc | C12: Ép cọc đại trà các hạng mục phụ trợ (nhà xe, nhà đóng container) | D12: Chi tiết | E12: 60 | F12: 46218 | G12: 46278 | H12: =G12-F12 -> 60 | I12: =IF(ABS(H12-E12)<1,"OK","Lệch") -> OK | J12: =MAX(0,MIN(1,($D$3-F12)/(G12-F12))) -> 1 | K12: =IF($D$3<F12,"Chưa bắt đầu",IF($D$3>G12,"Đến hạn xong","Đang thi công")) -> Đến hạn xong | L12: =IF(AND(D12="Chi tiết",F12<=$G$4,G12>=$F$4),"Có","") | M12: =MAX($G$8:$G$92)-G12 -> 186
A13: 6 | B13: Tổng hợp | C13: II. TIẾN ĐỘ XÂY DỰNG | D13: Tổng hợp | E13: 270 | F13: 46194 | G13: 46464 | H13: =G13-F13 -> 270 | I13: =IF(ABS(H13-E13)<1,"OK","Lệch") -> OK | J13: =MAX(0,MIN(1,($D$3-F13)/(G13-F13))) -> 0.38888889 | K13: =IF($D$3<F13,"Chưa bắt đầu",IF($D$3>G13,"Đến hạn xong","Đang thi công")) -> Đang thi công | L13: =IF(AND(D13="Chi tiết",F13<=$G$4,G13>=$F$4),"Có","") | M13: =MAX($G$8:$G$92)-G13 -> 0
A14: 7 | B14: Chuẩn bị | C14: A. CÔNG TÁC CHUẨN BỊ | D14: Tổng hợp | E14: 188.88 | F14: 46194 | G14: 46382 | H14: =G14-F14 -> 188 | I14: =IF(ABS(H14-E14)<1,"OK","Lệch") -> OK | J14: =MAX(0,MIN(1,($D$3-F14)/(G14-F14))) -> 0.55851064 | K14: =IF($D$3<F14,"Chưa bắt đầu",IF($D$3>G14,"Đến hạn xong","Đang thi công")) -> Đang thi công | L14: =IF(AND(D14="Chi tiết",F14<=$G$4,G14>=$F$4),"Có","") | M14: =MAX($G$8:$G$92)-G14 -> 82 | N14: Số ngày lẻ 188,88; kéo dài đến 26/12/2026 theo ID 8 (RuiRo #3).
A15: 8 | B15: Chuẩn bị | C15: Văn phòng tạm | D15: Chi tiết | E15: 24 | F15: 46194 | G15: 46382 | H15: =G15-F15 -> 188 | I15: =IF(ABS(H15-E15)<1,"OK","Lệch") -> Lệch | J15: =MAX(0,MIN(1,($D$3-F15)/(G15-F15))) -> 0.55851064 | K15: =IF($D$3<F15,"Chưa bắt đầu",IF($D$3>G15,"Đến hạn xong","Đang thi công")) -> Đang thi công | L15: =IF(AND(D15="Chi tiết",F15<=$G$4,G15>=$F$4),"Có","") | M15: =MAX($G$8:$G$92)-G15 -> 82 | N15: Số ngày 24 không khớp khoảng 21/6–26/12 (188 ngày) (RuiRo #3).
A16: 9 | B16: Chuẩn bị | C16: Bãi gia công | D16: Chi tiết | E16: 15 | F16: 46194 | G16: 46209 | H16: =G16-F16 -> 15 | I16: =IF(ABS(H16-E16)<1,"OK","Lệch") -> OK | J16: =MAX(0,MIN(1,($D$3-F16)/(G16-F16))) -> 1 | K16: =IF($D$3<F16,"Chưa bắt đầu",IF($D$3>G16,"Đến hạn xong","Đang thi công")) -> Đến hạn xong | L16: =IF(AND(D16="Chi tiết",F16<=$G$4,G16>=$F$4),"Có","") | M16: =MAX($G$8:$G$92)-G16 -> 255
A17: 10 | B17: Chuẩn bị | C17: Kết nối hệ thống điện nước tạm | D17: Chi tiết | E17: 15 | F17: 46194 | G17: 46209 | H17: =G17-F17 -> 15 | I17: =IF(ABS(H17-E17)<1,"OK","Lệch") -> OK | J17: =MAX(0,MIN(1,($D$3-F17)/(G17-F17))) -> 1 | K17: =IF($D$3<F17,"Chưa bắt đầu",IF($D$3>G17,"Đến hạn xong","Đang thi công")) -> Đến hạn xong | L17: =IF(AND(D17="Chi tiết",F17<=$G$4,G17>=$F$4),"Có","") | M17: =MAX($G$8:$G$92)-G17 -> 255
A18: 11 | B18: Tổng hợp | C18: B. CÔNG TÁC THI CÔNG | D18: Tổng hợp | E18: 270 | F18: 46194 | G18: 46464 | H18: =G18-F18 -> 270 | I18: =IF(ABS(H18-E18)<1,"OK","Lệch") -> OK | J18: =MAX(0,MIN(1,($D$3-F18)/(G18-F18))) -> 0.38888889 | K18: =IF($D$3<F18,"Chưa bắt đầu",IF($D$3>G18,"Đến hạn xong","Đang thi công")) -> Đang thi công | L18: =IF(AND(D18="Chi tiết",F18<=$G$4,G18>=$F$4),"Có","") | M18: =MAX($G$8:$G$92)-G18 -> 0
A19: 12 | B19: Nhà văn phòng | C19: 1. NHÀ VĂN PHÒNG | D19: Tổng hợp | E19: 120 | F19: 46240 | G19: 46360 | H19: =G19-F19 -> 120 | I19: =IF(ABS(H19-E19)<1,"OK","Lệch") -> OK | J19: =MAX(0,MIN(1,($D$3-F19)/(G19-F19))) -> 0.49166667 | K19: =IF($D$3<F19,"Chưa bắt đầu",IF($D$3>G19,"Đến hạn xong","Đang thi công")) -> Đang thi công | L19: =IF(AND(D19="Chi tiết",F19<=$G$4,G19>=$F$4),"Có","") | M19: =MAX($G$8:$G$92)-G19 -> 104
A20: 13 | B20: Nhà văn phòng | C20: Công tác kết cấu | D20: Tổng hợp | E20: 80 | F20: 46240 | G20: 46320 | H20: =G20-F20 -> 80 | I20: =IF(ABS(H20-E20)<1,"OK","Lệch") -> OK | J20: =MAX(0,MIN(1,($D$3-F20)/(G20-F20))) -> 0.7375 | K20: =IF($D$3<F20,"Chưa bắt đầu",IF($D$3>G20,"Đến hạn xong","Đang thi công")) -> Đang thi công | L20: =IF(AND(D20="Chi tiết",F20<=$G$4,G20>=$F$4),"Có","") | M20: =MAX($G$8:$G$92)-G20 -> 144
A21: 14 | B21: Nhà văn phòng | C21: Đào đất, thi công móng, cổ cột | D21: Chi tiết | E21: 30 | F21: 46240 | G21: 46270 | H21: =G21-F21 -> 30 | I21: =IF(ABS(H21-E21)<1,"OK","Lệch") -> OK | J21: =MAX(0,MIN(1,($D$3-F21)/(G21-F21))) -> 1 | K21: =IF($D$3<F21,"Chưa bắt đầu",IF($D$3>G21,"Đến hạn xong","Đang thi công")) -> Đến hạn xong | L21: =IF(AND(D21="Chi tiết",F21<=$G$4,G21>=$F$4),"Có","") | M21: =MAX($G$8:$G$92)-G21 -> 194
A22: 15 | B22: Nhà văn phòng | C22: Thi công sàn trệt | D22: Chi tiết | E22: 20 | F22: 46255 | G22: 46275 | H22: =G22-F22 -> 20 | I22: =IF(ABS(H22-E22)<1,"OK","Lệch") -> OK | J22: =MAX(0,MIN(1,($D$3-F22)/(G22-F22))) -> 1 | K22: =IF($D$3<F22,"Chưa bắt đầu",IF($D$3>G22,"Đến hạn xong","Đang thi công")) -> Đến hạn xong | L22: =IF(AND(D22="Chi tiết",F22<=$G$4,G22>=$F$4),"Có","") | M22: =MAX($G$8:$G$92)-G22 -> 189
A23: 16 | B23: Nhà văn phòng | C23: Thi công sàn tầng 2 | D23: Chi tiết | E23: 25 | F23: 46275 | G23: 46300 | H23: =G23-F23 -> 25 | I23: =IF(ABS(H23-E23)<1,"OK","Lệch") -> OK | J23: =MAX(0,MIN(1,($D$3-F23)/(G23-F23))) -> 0.96 | K23: =IF($D$3<F23,"Chưa bắt đầu",IF($D$3>G23,"Đến hạn xong","Đang thi công")) -> Đang thi công | L23: =IF(AND(D23="Chi tiết",F23<=$G$4,G23>=$F$4),"Có","") | M23: =MAX($G$8:$G$92)-G23 -> 164
A24: 17 | B24: Nhà văn phòng | C24: Thi công mái | D24: Chi tiết | E24: 20 | F24: 46300 | G24: 46320 | H24: =G24-F24 -> 20 | I24: =IF(ABS(H24-E24)<1,"OK","Lệch") -> OK | J24: =MAX(0,MIN(1,($D$3-F24)/(G24-F24))) -> 0 | K24: =IF($D$3<F24,"Chưa bắt đầu",IF($D$3>G24,"Đến hạn xong","Đang thi công")) -> Chưa bắt đầu | L24: =IF(AND(D24="Chi tiết",F24<=$G$4,G24>=$F$4),"Có","") | M24: =MAX($G$8:$G$92)-G24 -> 144
A25: 18 | B25: Nhà văn phòng | C25: Kết cấu thép | D25: Tổng hợp | E25: 20 | F25: 46250 | G25: 46270 | H25: =G25-F25 -> 20 | I25: =IF(ABS(H25-E25)<1,"OK","Lệch") -> OK | J25: =MAX(0,MIN(1,($D$3-F25)/(G25-F25))) -> 1 | K25: =IF($D$3<F25,"Chưa bắt đầu",IF($D$3>G25,"Đến hạn xong","Đang thi công")) -> Đến hạn xong | L25: =IF(AND(D25="Chi tiết",F25<=$G$4,G25>=$F$4),"Có","") | M25: =MAX($G$8:$G$92)-G25 -> 194
A26: 19 | B26: Nhà văn phòng | C26: Lắp dựng cột, kèo, xà gồ, giằng | D26: Chi tiết | E26: 20 | F26: 46250 | G26: 46270 | H26: =G26-F26 -> 20 | I26: =IF(ABS(H26-E26)<1,"OK","Lệch") -> OK | J26: =MAX(0,MIN(1,($D$3-F26)/(G26-F26))) -> 1 | K26: =IF($D$3<F26,"Chưa bắt đầu",IF($D$3>G26,"Đến hạn xong","Đang thi công")) -> Đến hạn xong | L26: =IF(AND(D26="Chi tiết",F26<=$G$4,G26>=$F$4),"Có","") | M26: =MAX($G$8:$G$92)-G26 -> 194 | N26: Dựng thép khi móng VP (ID 14) chưa xong (đến 5/9) – cần phân khu (RuiRo #4).
A27: 20 | B27: Nhà văn phòng | C27: Công tác MEPF | D27: Tổng hợp | E27: 60 | F27: 46255 | G27: 46315 | H27: =G27-F27 -> 60 | I27: =IF(ABS(H27-E27)<1,"OK","Lệch") -> OK | J27: =MAX(0,MIN(1,($D$3-F27)/(G27-F27))) -> 0.73333333 | K27: =IF($D$3<F27,"Chưa bắt đầu",IF($D$3>G27,"Đến hạn xong","Đang thi công")) -> Đang thi công | L27: =IF(AND(D27="Chi tiết",F27<=$G$4,G27>=$F$4),"Có","") | M27: =MAX($G$8:$G$92)-G27 -> 149
A28: 21 | B28: Nhà văn phòng | C28: Lắp đặt hệ thống MEP | D28: Chi tiết | E28: 45 | F28: 46255 | G28: 46300 | H28: =G28-F28 -> 45 | I28: =IF(ABS(H28-E28)<1,"OK","Lệch") -> OK | J28: =MAX(0,MIN(1,($D$3-F28)/(G28-F28))) -> 0.97777778 | K28: =IF($D$3<F28,"Chưa bắt đầu",IF($D$3>G28,"Đến hạn xong","Đang thi công")) -> Đang thi công | L28: =IF(AND(D28="Chi tiết",F28<=$G$4,G28>=$F$4),"Có","") | M28: =MAX($G$8:$G$92)-G28 -> 164
A29: 22 | B29: Nhà văn phòng | C29: Test hệ thống MEP | D29: Chi tiết | E29: 15 | F29: 46300 | G29: 46315 | H29: =G29-F29 -> 15 | I29: =IF(ABS(H29-E29)<1,"OK","Lệch") -> OK | J29: =MAX(0,MIN(1,($D$3-F29)/(G29-F29))) -> 0 | K29: =IF($D$3<F29,"Chưa bắt đầu",IF($D$3>G29,"Đến hạn xong","Đang thi công")) -> Chưa bắt đầu | L29: =IF(AND(D29="Chi tiết",F29<=$G$4,G29>=$F$4),"Có","") | M29: =MAX($G$8:$G$92)-G29 -> 149
A30: 23 | B30: Nhà văn phòng | C30: Công tác kiến trúc | D30: Tổng hợp | E30: 60 | F30: 46300 | G30: 46360 | H30: =G30-F30 -> 60 | I30: =IF(ABS(H30-E30)<1,"OK","Lệch") -> OK | J30: =MAX(0,MIN(1,($D$3-F30)/(G30-F30))) -> 0 | K30: =IF($D$3<F30,"Chưa bắt đầu",IF($D$3>G30,"Đến hạn xong","Đang thi công")) -> Chưa bắt đầu | L30: =IF(AND(D30="Chi tiết",F30<=$G$4,G30>=$F$4),"Có","") | M30: =MAX($G$8:$G$92)-G30 -> 104
A31: 24 | B31: Nhà văn phòng | C31: Hoàn thiện nhà | D31: Chi tiết | E31: 60 | F31: 46300 | G31: 46360 | H31: =G31-F31 -> 60 | I31: =IF(ABS(H31-E31)<1,"OK","Lệch") -> OK | J31: =MAX(0,MIN(1,($D$3-F31)/(G31-F31))) -> 0 | K31: =IF($D$3<F31,"Chưa bắt đầu",IF($D$3>G31,"Đến hạn xong","Đang thi công")) -> Chưa bắt đầu | L31: =IF(AND(D31="Chi tiết",F31<=$G$4,G31>=$F$4),"Có","") | M31: =MAX($G$8:$G$92)-G31 -> 104
A32: 25 | B32: Nhà văn phòng | C32: Vệ sinh & bàn giao | D32: Chi tiết | E32: 7 | F32: 46353 | G32: 46360 | H32: =G32-F32 -> 7 | I32: =IF(ABS(H32-E32)<1,"OK","Lệch") -> OK | J32: =MAX(0,MIN(1,($D$3-F32)/(G32-F32))) -> 0 | K32: =IF($D$3<F32,"Chưa bắt đầu",IF($D$3>G32,"Đến hạn xong","Đang thi công")) -> Chưa bắt đầu | L32: =IF(AND(D32="Chi tiết",F32<=$G$4,G32>=$F$4),"Có","") | M32: =MAX($G$8:$G$92)-G32 -> 104
A33: 26 | B33: Hạ tầng | C33: 2. CÔNG TÁC HẠ TẦNG | D33: Tổng hợp | E33: 186 | F33: 46278 | G33: 46464 | H33: =G33-F33 -> 186 | I33: =IF(ABS(H33-E33)<1,"OK","Lệch") -> OK | J33: =MAX(0,MIN(1,($D$3-F33)/(G33-F33))) -> 0.11290323 | K33: =IF($D$3<F33,"Chưa bắt đầu",IF($D$3>G33,"Đến hạn xong","Đang thi công")) -> Đang thi công | L33: =IF(AND(D33="Chi tiết",F33<=$G$4,G33>=$F$4),"Có","") | M33: =MAX($G$8:$G$92)-G33 -> 0
A34: 27 | B34: Hạ tầng | C34: Hệ thống thoát nước mưa | D34: Chi tiết | E34: 120 | F34: 46278 | G34: 46398 | H34: =G34-F34 -> 120 | I34: =IF(ABS(H34-E34)<1,"OK","Lệch") -> OK | J34: =MAX(0,MIN(1,($D$3-F34)/(G34-F34))) -> 0.175 | K34: =IF($D$3<F34,"Chưa bắt đầu",IF($D$3>G34,"Đến hạn xong","Đang thi công")) -> Đang thi công | L34: =IF(AND(D34="Chi tiết",F34<=$G$4,G34>=$F$4),"Có","") | M34: =MAX($G$8:$G$92)-G34 -> 66
A35: 28 | B35: Hạ tầng | C35: Hệ thống thoát nước thải | D35: Chi tiết | E35: 120 | F35: 46278 | G35: 46398 | H35: =G35-F35 -> 120 | I35: =IF(ABS(H35-E35)<1,"OK","Lệch") -> OK | J35: =MAX(0,MIN(1,($D$3-F35)/(G35-F35))) -> 0.175 | K35: =IF($D$3<F35,"Chưa bắt đầu",IF($D$3>G35,"Đến hạn xong","Đang thi công")) -> Đang thi công | L35: =IF(AND(D35="Chi tiết",F35<=$G$4,G35>=$F$4),"Có","") | M35: =MAX($G$8:$G$92)-G35 -> 66
A36: 29 | B36: Hạ tầng | C36: Đường nội bộ (hoàn thành cấp phối) | D36: Chi tiết | E36: 120 | F36: 46293 | G36: 46413 | H36: =G36-F36 -> 120 | I36: =IF(ABS(H36-E36)<1,"OK","Lệch") -> OK | J36: =MAX(0,MIN(1,($D$3-F36)/(G36-F36))) -> 0.05 | K36: =IF($D$3<F36,"Chưa bắt đầu",IF($D$3>G36,"Đến hạn xong","Đang thi công")) -> Đang thi công | L36: =IF(AND(D36="Chi tiết",F36<=$G$4,G36>=$F$4),"Có","") | M36: =MAX($G$8:$G$92)-G36 -> 51
A37: 30 | B37: Hạ tầng | C37: Bó vỉa và cảnh quan | D37: Chi tiết | E37: 60 | F37: 46383 | G37: 46443 | H37: =G37-F37 -> 60 | I37: =IF(ABS(H37-E37)<1,"OK","Lệch") -> OK | J37: =MAX(0,MIN(1,($D$3-F37)/(G37-F37))) -> 0 | K37: =IF($D$3<F37,"Chưa bắt đầu",IF($D$3>G37,"Đến hạn xong","Đang thi công")) -> Chưa bắt đầu | L37: =IF(AND(D37="Chi tiết",F37<=$G$4,G37>=$F$4),"Có","") -> Có | M37: =MAX($G$8:$G$92)-G37 -> 21
A38: 31 | B38: Hạ tầng | C38: Kết nối hệ thống hiện hữu | D38: Chi tiết | E38: 30 | F38: 46413 | G38: 46443 | H38: =G38-F38 -> 30 | I38: =IF(ABS(H38-E38)<1,"OK","Lệch") -> OK | J38: =MAX(0,MIN(1,($D$3-F38)/(G38-F38))) -> 0 | K38: =IF($D$3<F38,"Chưa bắt đầu",IF($D$3>G38,"Đến hạn xong","Đang thi công")) -> Chưa bắt đầu | L38: =IF(AND(D38="Chi tiết",F38<=$G$4,G38>=$F$4),"Có","") -> Có | M38: =MAX($G$8:$G$92)-G38 -> 21
A39: 32 | B39: Hạ tầng | C39: Hoàn thiện đường nội bộ | D39: Chi tiết | E39: 45 | F39: 46419 | G39: 46464 | H39: =G39-F39 -> 45 | I39: =IF(ABS(H39-E39)<1,"OK","Lệch") -> OK | J39: =MAX(0,MIN(1,($D$3-F39)/(G39-F39))) -> 0 | K39: =IF($D$3<F39,"Chưa bắt đầu",IF($D$3>G39,"Đến hạn xong","Đang thi công")) -> Chưa bắt đầu | L39: =IF(AND(D39="Chi tiết",F39<=$G$4,G39>=$F$4),"Có","") -> Có | M39: =MAX($G$8:$G$92)-G39 -> 0 | N39: Kết thúc đúng mốc cuối 18/3, trùng Tết (RuiRo #7).
A40: 33 | B40: Nhà bảo vệ & hàng rào | C40: 3. NHÀ BẢO VỆ VÀ HÀNG RÀO | D40: Chi tiết | E40: 180 | F40: 46218 | G40: 46398 | H40: =G40-F40 -> 180 | I40: =IF(ABS(H40-E40)<1,"OK","Lệch") -> OK | J40: =MAX(0,MIN(1,($D$3-F40)/(G40-F40))) -> 0.45 | K40: =IF($D$3<F40,"Chưa bắt đầu",IF($D$3>G40,"Đến hạn xong","Đang thi công")) -> Đang thi công | L40: =IF(AND(D40="Chi tiết",F40<=$G$4,G40>=$F$4),"Có","") | M40: =MAX($G$8:$G$92)-G40 -> 66
...

Sheet NguonLuc
A1: NGUỒN LỰC: BAN CHỈ HUY – CÔNG NHẬT – THIẾT BỊ – VẬN CHUYỂN
A2: Nguồn: Bảng khối lượng Prelim (Pre_Manpower, Pre_Vanchuyen, Pre_Cauthap, Prelims). Không nêu lương từng vị trí; chi phí xem sheet ChiPhi.
A3: 1. BAN CHỈ HUY CÔNG TRƯỜNG (chỉ liệt kê vị trí có số lượng ≥ 1)
A4: STT | B4: Chức danh | C4: Số lượng | D4: Thời gian (tháng) | E4: Bắt đầu | F4: Kết thúc | G4: Nhóm | H4: Ghi chú
A5: 1 | B5: Giám đốc dự án | C5: 1 | D5: 9 | E5: 46204 | F5: 46474 | G5: Quản lý
A6: 2 | B6: Chỉ huy trưởng | C6: 1 | D6: 10 | E6: 46204 | F6: 46504 | G6: Quản lý
A7: 3 | B7: Trưởng nhóm KS giám sát xây dựng | C7: 1 | D7: 9 | E7: 46204 | F7: 46474 | G7: Xây dựng
A8: 4 | B8: KS Giám sát xây dựng | C8: 1 | D8: 10 | E8: 46204 | F8: 46504 | G8: Xây dựng
A9: 5 | B9: KS Giám sát xây dựng | C9: 1 | D9: 9 | E9: 46204 | F9: 46474 | G9: Xây dựng
A10: 6 | B10: KS Giám sát hạ tầng | C10: 1 | D10: 9 | E10: 46204 | F10: 46474 | G10: Hạ tầng
A11: 7 | B11: KS Giám sát M&E | C11: 1 | D11: 9 | E11: 46204 | F11: 46474 | G11: M&E
A12: 8 | B12: KS Shopdrawing + biện pháp, 2 BIM | C12: 1 | D12: 8 | E12: 46204 | F12: 46444 | G12: Kỹ thuật – shopdrawing
A13: 9 | B13: KS QA/QC | C13: 1 | D13: 11 | E13: 46204 | F13: 46534 | G13: QA/QC
A14: 10 | B14: KS QS | C14: 1 | D14: 10 | E14: 46204 | F14: 46504 | G14: QS
A15: 11 | B15: An toàn viên | C15: 1 | D15: 9 | E15: 46204 | F15: 46474 | G15: HSSE
A16: 12 | B16: Kế toán | C16: 1 | D16: 8 | E16: 46204 | F16: 46444 | G16: Hành chính – kế toán
A17: 13 | B17: Thủ kho | C17: 1 | D17: 8 | E17: 46204 | F17: 46444 | G17: Kho
B18: TỔNG BAN CHỈ HUY | C18: =SUM(C5:C17) -> 13
A19: Vị trí có trong bảng nhưng số lượng = 0 (không bố trí): Chủ trì thiết kế, Chỉ huy phó, Quản lý tiến độ, Trưởng nhóm & KS giám sát kết cấu thép, Trưởng nhóm giám sát hạ tầng/M&E, Trắc đạc, Trưởng ban HSSE, Y tá, Phiên dịch, KS LEED → xem RuiRo #8, #9.
A21: 2. BIỂU ĐỒ NHÂN SỰ BAN CHỈ HUY THEO THÁNG (tính từ ngày bố trí theo Prelim)
B22: Tháng | C22: 46204 | D22: =EDATE(C22,1) -> 46235 | E22: =EDATE(D22,1) -> 46266 | F22: =EDATE(E22,1) -> 46296 | G22: =EDATE(F22,1) -> 46327 | H22: =EDATE(G22,1) -> 46357 | I22: =EDATE(H22,1) -> 46388 | J22: =EDATE(I22,1) -> 46419 | K22: =EDATE(J22,1) -> 46447 | ... M22: =EDATE(L22,1) -> 46508
B23: Số BCH có mặt (người) | C23: =SUMPRODUCT(($C$5:$C$17)*($E$5:$E$17<=EOMONTH(C22,0))*($F$5:$F$17>=C22)) -> 13 | D23: =SUMPRODUCT(($C$5:$C$17)*($E$5:$E$17<=EOMONTH(D22,0))*($F$5:$F$17>=D22)) -> 13 | E23: =SUMPRODUCT(($C$5:$C$17)*($E$5:$E$17<=EOMONTH(E22,0))*($F$5:$F$17>=E22)) -> 13 | F23: =SUMPRODUCT(($C$5:$C$17)*($E$5:$E$17<=EOMONTH(F22,0))*($F$5:$F$17>=F22)) -> 13 | G23: =SUMPRODUCT(($C$5:$C$17)*($E$5:$E$17<=EOMONTH(G22,0))*($F$5:$F$17>=G22)) -> 13 | H23: =SUMPRODUCT(($C$5:$C$17)*($E$5:$E$17<=EOMONTH(H22,0))*($F$5:$F$17>=H22)) -> 13 | I23: =SUMPRODUCT(($C$5:$C$17)*($E$5:$E$17<=EOMONTH(I22,0))*($F$5:$F$17>=I22)) -> 13 | J23: =SUMPRODUCT(($C$5:$C$17)*($E$5:$E$17<=EOMONTH(J22,0))*($F$5:$F$17>=J22)) -> 13 | ... M23: =SUMPRODUCT(($C$5:$C$17)*($E$5:$E$17<=EOMONTH(M22,0))*($F$5:$F$17>=M22)) -> 1
B24: Ghi chú: một số vị trí (Chỉ huy trưởng, KS giám sát xây dựng, KS QA/QC, KS QS) bố trí kéo dài đến 27/4–27/5/2027, sau ngày hoàn thành 18/3/2027 để hoàn công/bàn giao.
A26: 3. SO SÁNH MỐC THỜI GIAN GIỮA TIẾN ĐỘ VÀ BẢNG KHỐI LƯỢNG PRELIM
B27: Chỉ tiêu | C27: Tiến độ (Rev 01) | D27: Prelim (Rev 00) | E27: Lệch (ngày) | H27: Nhận xét
B28: Ngày bắt đầu | C28: =MIN(TienDo!$F$8:$F$92) -> 46194 | D28: 46204 | E28: =D28-C28 -> 10 | H28: Cả hai đều 270 ngày nhưng Prelim lệch +10 ngày: BCH/công nhật/thiết bị tính từ 01/07/2026, trong khi công tác chuẩn bị bắt đầu 21/06/2026 (RuiRo #1).
B29: Ngày kết thúc | C29: =MAX(TienDo!$G$8:$G$92) -> 46464 | D29: 46474 | E29: =D29-C29 -> 10
A31: 4. CÔNG NHẬT (theo Pre_Manpower)
A32: STT | B32: Công việc | C32: Số lượng (người) | D32: Thời gian (tháng) | E32: Bắt đầu | F32: Kết thúc | H32: Ghi chú
A33: 1 | B33: Công nhật tiện ích điện nước | C33: 1 | D33: 9 | E33: 46204 | F33: 46474
A34: 2 | B34: Công nhật dọn vệ sinh công trường | C34: 2 | D34: 9 | E34: 46204 | F34: 46474
A35: 3 | B35: Công nhật dọn vệ sinh bàn giao | C35: 4 | D35: 1 | E35: 46444 | F35: 46474 | H35: Gắn với ID 85
A36: Công nhân thi công trực tiếp cao điểm: 250 người (hệ số dự phòng PPE 1,2) – theo Pre_HSSE / TH_Chiphichuanbi_TC. Bảng Prelim KHÔNG có biểu đồ nhân lực công nhân theo tháng/tổ đội → cần bổ sung khi có bảng khối lượng chính (RuiRo #16).
A38: 5. THIẾT BỊ THI CÔNG & VẬN CHUYỂN
A39: STT | B39: Hạng mục | C39: ĐVT | D39: Số lượng | E39: Thành tiền (VND) | F39: Thời gian | G39: Nguồn | H39: Ghi chú
A40: 1 | B40: Cẩu Kato, cẩu thùng | C40: Lot | D40: 1 | E40: 1800000000 | F40: Cả dự án | G40: Prelims #44 | H40: Dựng thép nhiều mặt trận đồng thời (RuiRo #17)
A41: 2 | B41: Thiết bị cơ giới hỗ trợ thi công | C41: Lot | D41: 1 | E41: 45000000 | F41: Cả dự án | G41: Prelims #45A
A42: 3 | B42: Cẩu tháp / vận thăng | C42: cái | D42: 0 | E42: 0 | F42: — | G42: Pre_Cauthap, Prelims #45 | H42: Không bố trí (KL = 0)
A43: 4 | B43: Xe ủi D31, xe cuốc 0,5 m³ (tháng 7/2026) | C43: tháng | D43: 0 | E43: 0 | F43: — | G43: Pre_Manpower | H43: KL = 0 – cơ giới san lấp do tổ thi công hạ tầng tự bố trí? cần xác nhận
A44: 5 | B44: Vận chuyển thiết bị thi công tạm: 2 chuyến đi + 2 chuyến về | C44: hạng mục | D44: 1 | E44: 60000000 | F44: 01/07/2026–28/03/2027 | G44: Pre_Vanchuyen
...

Sheet BienPhap
A1: BIỆN PHÁP TỔ CHỨC THI CÔNG: CÔNG TRÌNH TẠM – ĐIỆN NƯỚC TẠM – CHỈ SỐ KHỐI LƯỢNG
A2: Nguồn: Prelim (Pre_Congtrinhtam, Pre_Diennuoctam, GIAN GIAO, VS BAN GIAO). Chỉ liệt kê hạng mục có khối lượng > 0.
A3: 1. CÔNG TRÌNH TẠM & TIỆN ÍCH CÔNG TRƯỜNG
A4: STT | B4: Hạng mục | C4: ĐVT | D4: Khối lượng | E4: Quy cách / diễn giải | F4: Thời gian theo tiến độ | G4: Nguồn
A5: 1 | B5: Văn phòng nhà thầu: container 40ft | C5: cái | D5: 2 | E5: Thuê, vận chuyển đi/về, sơn màu AZB; mái che KCT 2 × (12×4 m) = 96 m²; nội thất: 15 bàn + 15 ghế làm việc, bàn họp 1 + 10 ghế, 2 tủ hồ sơ, TV 55", máy chấm công | F5: =TEXT(TienDo!$F$15,"dd/mm/yyyy")&" – "&TEXT(TienDo!$G$15,"dd/mm/yyyy") -> 21/06/2026 – 26/12/2026 | G5: Pre_Congtrinhtam (ID 8)
A6: 2 | B6: Nhà vệ sinh BCH: container 10ft + hầm tự hoại | C6: cái | D6: 1 | E6: Thuê, vận chuyển, sơn màu AZB | F6: Suốt dự án | G6: Pre_Congtrinhtam
A7: 3 | B7: Nhà vệ sinh công nhân: container 10ft + hầm tự hoại | C7: cái | D7: 2 | E7: 2 container cho ~250 công nhân → kiểm tra theo QCVN 18:2014/BXD (RuiRo #12) | F7: Suốt dự án | G7: Pre_Congtrinhtam
A8: 4 | B8: Nhà kho kín kết cấu thép | C8: m² | D8: 60 | E8: 10 × 6 m; nền đá 0x4 + bê tông M150 dày 5 cm (3 m³); lắp đặt & tháo dỡ 60 m² | F8: Suốt dự án | G8: Pre_Congtrinhtam
A9: 5 | B9: Bãi gia công thép (kết cấu thép) | C9: m² | D9: 160 | E9: 20 × 8 m; nền đá 4x6 (8 m³) + đá 0x4 (16 m³); lắp đặt & tháo dỡ 160 m² | F9: =TEXT(TienDo!$F$16,"dd/mm/yyyy")&" – "&TEXT(TienDo!$G$16,"dd/mm/yyyy") -> 21/06/2026 – 06/07/2026 | G9: Pre_Congtrinhtam (ID 9)
A10: 6 | B10: Chòi bảo vệ (khung thép) | C10: cái | D10: 1 | E10: Lắp đặt, sơn, tháo dỡ | F10: Suốt dự án | G10: Pre_Congtrinhtam
A11: 7 | B11: Bảng thông tin dự án, cột cờ 3 cột, bồn hoa | C11: lot | D11: 1 | E11: Bảng thông tin tại vị trí 1 bộ; lắp đặt & tháo dỡ bảng hiệu cổng 1 bộ | F11: Đầu dự án | G11: Pre_Congtrinhtam
A12: 8 | B12: Hệ thống chiếu sáng công trình | C12: bộ | D12: 50 | E12: 50 đèn pha LED 150W; cáp 3C-2.5 mm² 750 m; cáp 4×4 mm² 200 m; 140 cây ống kẽm D90×6 m làm trụ | F12: =TEXT(TienDo!$F$17,"dd/mm/yyyy")&" – "&TEXT(TienDo!$G$17,"dd/mm/yyyy") -> 21/06/2026 – 06/07/2026 | G12: Pre_Diennuoctam (ID 10)
A13: 9 | B13: Chiếu sáng văn phòng | C13: bộ | D13: 20 | E13: 20 đèn LED 1×1 m 2 bóng 18W; 40 mặt công tắc, 40 mặt ổ cắm | F13: =TEXT(TienDo!$F$17,"dd/mm/yyyy")&" – "&TEXT(TienDo!$G$17,"dd/mm/yyyy") -> 21/06/2026 – 06/07/2026 | G13: Pre_Diennuoctam (ID 10)
A14: 10 | B14: Bồn chứa nước 2 m³ | C14: cái | D14: 7 | E14: Tổng 14 m³; ống nhựa mềm D27 1.000 m; 4 máy xịt áp lực xách tay + 4 máy 3 pha | F14: =TEXT(TienDo!$F$17,"dd/mm/yyyy")&" – "&TEXT(TienDo!$G$17,"dd/mm/yyyy") -> 21/06/2026 – 06/07/2026 | G14: Pre_Diennuoctam (ID 10)
A15: 11 | B15: Chống sét tạm | C15: hệ | D15: 2 | E15: Mỗi hệ: kim thu sét + giếng khoan sâu 20 m + cọc tiếp địa; cáp đồng trần 70 mm² 300 m | F15: Suốt dự án | G15: Pre_Diennuoctam
A16: 12 | B16: Camera an ninh công trường | C16: hệ | D16: 1 | E16: 1 camera cố định + 4 camera PTZ 32×, NVR 16 kênh, ổ cứng 4 TB, cáp quang 1.200 m | F16: Suốt dự án | G16: Pre_Diennuoctam
A17: 13 | B17: Điện, nước, điện thoại – internet hàng tháng | C17: tháng | D17: 9.03 | E17: Điện, nước tiêu thụ và internet tính theo ~9,03 tháng | F17: Suốt dự án | G17: Pre_Diennuoctam
A18: Khối lượng = 0 trong bảng Prelim (cần xác nhận bên chịu trách nhiệm): trạm biến áp 250 kVA, dây ABC, tủ điện tạm DB-T1, đấu nối điện/nước tạm, máy phát điện, đồng hồ nước D60, văn phòng CĐT & tư vấn, hàng rào tạm & cổng tạm (ghi chú: thầu AB chịu trách nhiệm), cầu rửa xe, nhà huấn luyện an toàn, bãi tập kết ngoài trời, nhà chứa rác/mẫu, chòi hút thuốc (RuiRo #10, #11).
A20: 2. CHỈ SỐ KHỐI LƯỢNG & NĂNG SUẤT YÊU CẦU (tính từ số liệu trong file)
A21: STT | B21: Chỉ số | C21: ĐVT | D21: Giá trị | E21: Cách tính / giả định | G21: Nguồn
A22: 1 | B22: Diện tích sàn xưởng (giả định = diện tích vệ sinh bàn giao) | C22: m² | D22: 27225 | E22: Giả định sàn nền BT xưởng = 27.225 m²; cần thay bằng KL bản vẽ | G22: VS BAN GIAO
A23: 2 | B23: Năng suất đổ BT sàn nền xưởng yêu cầu | C23: m²/ngày | D23: =D22/TienDo!$E$52 -> 302.5 | E23: Diện tích ÷ số ngày ID 45 (90 ngày lịch) | G23: TienDo ID 45
A24: 3 | B24: Diện tích mỗi phân khu (3 phân khu trục 1-15, 15-30, 30-42) | C24: m² | D24: =D22/3 -> 9075 | E24: Mỗi phân khu 30 ngày (ID 46–48); giả định chia đều | G24: TienDo ID 46–48
A25: 4 | B25: Diện tích giàn giáo bao che ngoài nhà | C25: m² | D25: 3080.9 | E25: 70 m × 12,9 m + 110 m × 8,6 m (phụ trợ xưởng) + 127 m × 9,7 m (văn phòng 2 tầng) | G25: GIAN GIAO
A26: 5 | B26: Chi phí giàn giáo bao che / m² | C26: VND/m² | D26: =ChiPhi!$F$67/D25 -> 81248.094 | E26: Prelims #50 ÷ diện tích (tham khảo) | G26: Prelims, GIAN GIAO
A27: 6 | B27: Diện tích vệ sinh bàn giao | C27: m² | D27: 36365 | E27: Xưởng 27.225 + VP 680×3 tầng + nhà xe 700×3 tầng + còn lại 5.000 | G27: VS BAN GIAO
A28: 7 | B28: Năng suất vệ sinh bàn giao yêu cầu | C28: m²/ngày | D28: =D27/TienDo!$E$92 -> 1212.1667 | E28: Diện tích ÷ 30 ngày (ID 85) – kèm 4 công nhật (26/02–28/03/2027) | G28: TienDo ID 85
A29: 8 | B29: Chi phí vệ sinh bàn giao / m² | C29: VND/m² | D29: =ChiPhi!$F$41/D27 -> 9516.7056 | E29: Prelims #31 ÷ diện tích | G29: Prelims
A30: 9 | B30: Diện tích vệ sinh nếu VP 2 tầng (theo tiến độ) và nhà xe 1 tầng | C30: m² | D30: =D27-680-1400 -> 34285 | E30: Trừ 1 tầng VP (680) và 2 tầng nhà xe (1.400) – giả định để đối chiếu (RuiRo #15) | G30: VS BAN GIAO

Sheet HSSE
A1: KẾ HOẠCH AN TOÀN – SỨC KHỎE – MÔI TRƯỜNG (HSSE)
A2: Nguồn: Pre_HSSE (Prelim) đối chiếu với tiến độ. Phần 4 là đề xuất chuyên môn để rà soát, không có trong file gốc.
A3: 1. QUY MÔ & NĂNG LỰC HSSE
A4: STT | B4: Chỉ tiêu | C4: Giá trị | D4: Đơn vị | E4: Ghi chú
A5: 1 | B5: Ban chỉ huy công trường | C5: =NguonLuc!$C$18 -> 13 | D5: người | E5: Từ sheet NguonLuc
A6: 2 | B6: Công nhân cao điểm | C6: 250 | D6: người | E6: Pre_HSSE / TH_Chiphichuanbi_TC
A7: 3 | B7: Hệ số dự phòng PPE | C7: 1.2 | D7: lần | E7: Pre_HSSE
A8: 4 | B8: An toàn viên bố trí | C8: 1 | D8: người | E8: Pre_Manpower (KS an toàn viên, 9 tháng); Trưởng ban HSSE = 0; Y tá = 0
A9: 5 | B9: Số công nhân / 1 an toàn viên | C9: =C6/C8 -> 250 | D9: người/người | E9: Nhiều mặt trận cùng lúc → rà soát (RuiRo #9)
A11: 2. HỒ SƠ PHÁP LÝ, BẢO HIỂM & HUẤN LUYỆN (thành tiền = SL × đơn giá)
A12: STT | B12: Nội dung | C12: ĐVT | D12: Số lượng | E12: Đơn giá (VND) | F12: Thành tiền (VND) | G12: Nguồn
A13: 1 | B13: Bảo hiểm TNLĐ kỹ sư | C13: Người | D13: 13 | E13: 165000 | F13: =D13*E13 -> 2145000 | G13: Pre_HSSE dòng 15
A14: 2 | B14: Khám sức khỏe kỹ sư | C14: Người | D14: 13 | E14: 100000 | F14: =D14*E14 -> 1300000 | G14: Pre_HSSE dòng 16
A15: 3 | B15: Huấn luyện an toàn các nhóm (Kỹ sư) | C15: Người | D15: 13 | E15: 200000 | F15: =D15*E15 -> 2600000 | G15: Pre_HSSE dòng 17
A16: 4 | B16: Bảo hiểm TNLĐ Công nhân (12 tháng SL tối thiểu cần để bổ sung hồ sơ PL) | C16: Người | D16: 250 | E16: 135000 | F16: =D16*E16 -> 33750000 | G16: Pre_HSSE dòng 18
A17: 5 | B17: Khám sức khỏe công nhân (06 tháng 1 lần SL tối thiểu cần để bổ sung hồ sơ PL) | C17: Người | D17: 250 | E17: 370000 | F17: =D17*E17 -> 92500000 | G17: Pre_HSSE dòng 19
A18: 6 | B18: Thẻ an toàn NĐ44 công nhân | C18: Người | D18: 250 | E18: 100000 | F18: =D18*E18 -> 25000000 | G18: Pre_HSSE dòng 20
A19: 7 | B19: Chứng chỉ nghề | C19: Người | D19: 42 | E19: 1000000 | F19: =D19*E19 -> 42000000 | G19: Pre_HSSE dòng 21
A20: 8 | B20: Chứng chỉ Sơ cấp cứu | C20: Người | D20: 5 | E20: 800000 | F20: =D20*E20 -> 4000000 | G20: Pre_HSSE dòng 22
A21: 9 | B21: Chứng chỉ PCCC BCH | C21: Người | D21: 40 | E21: 1100000 | F21: =D21*E21 -> 44000000 | G21: Pre_HSSE dòng 23
B22: Cộng nhóm 2 | F22: =SUM(F13:F21) -> 247295000 | G22: =IF(ABS(F22-ChiPhi!$F$13)<1,"Khớp Prelims #6","Lệch Prelims #6") -> Khớp Prelims #6
A24: 3. TRANG THIẾT BỊ HSSE CHÍNH (không phải toàn bộ danh mục; SL đã nhân hệ số dự phòng)
A25: STT | B25: Hạng mục | C25: ĐVT | D25: Tổng KL | E25: Đơn giá (VND) | F25: Thành tiền (VND) | G25: Nguồn
A26: 1 | B26: Nón công nhân | C26: Cái | D26: 250 | E26: 43000 | F26: =D26*E26 -> 10750000 | G26: Pre_HSSE dòng 37
A27: 2 | B27: Áo Phản quang công Nhân | C27: Cái | D27: 250 | E27: 30000 | F27: =D27*E27 -> 7500000 | G27: Pre_HSSE dòng 44
A28: 3 | B28: Áo mưa công nhân | C28: Cái | D28: 300 | E28: 30000 | F28: =D28*E28 -> 9000000 | G28: Pre_HSSE dòng 46
A29: 4 | B29: Giày công nhân | C29: Đôi | D29: 250 | E29: 85000 | F29: =D29*E29 -> 21250000 | G29: Pre_HSSE dòng 51
A30: 5 | B30: Ủng công nhân | C30: Đôi | D30: 300 | E30: 45000 | F30: =D30*E30 -> 13500000 | G30: Pre_HSSE dòng 54
A31: 6 | B31: Mặt Nạ Hàn | C31: Cái | D31: 60 | E31: 100000 | F31: =D31*E31 -> 6000000 | G31: Pre_HSSE dòng 57
A32: 7 | B32: Dây an toàn toàn thân ( 02 móc) | C32: Sợi | D32: 12 | E32: 175000 | F32: =D32*E32 -> 2100000 | G32: Pre_HSSE dòng 86
A33: 8 | B33: Dây an toàn toàn thân ( 01móc) | C33: Sợi | D33: 12 | E33: 175000 | F33: =D33*E33 -> 2100000 | G33: Pre_HSSE dòng 87
A34: 9 | B34: Dây cứu sinh màu cam ( cuộn 100m) | C34: cuộn | D34: 12 | E34: 1200000 | F34: =D34*E34 -> 14400000 | G34: Pre_HSSE dòng 88
A35: 10 | B35: Bình Chữa cháy CO2 3kg | C35: Cái | D35: 50 | E35: 36000 | F35: =D35*E35 -> 1800000 | G35: Pre_HSSE dòng 74
A36: 11 | B36: Bình bột 4kg | C36: Cái | D36: 50 | E36: 48000 | F36: =D36*E36 -> 2400000 | G36: Pre_HSSE dòng 75
A37: 12 | B37: Bình Bột 8kg | C37: Cái | D37: 50 | E37: 96000 | F37: =D37*E37 -> 4800000 | G37: Pre_HSSE dòng 76
... A49: 24 | B49: Bảng Exit | C49: Cái | D49: 6 | E49: 50000 | F49: =D49*E49 -> 300000 | G49: Pre_HSSE dòng 153
A51: 4. RỦI RO AN TOÀN THEO GIAI ĐOẠN THI CÔNG (ĐỀ XUẤT – dùng để rà soát)
A52: STT | B52: Giai đoạn (ID tiến độ) | C52: Từ | D52: Đến | E52: Rủi ro chính | F52: Biện pháp kiểm soát chủ yếu | G52: Nguồn lực HSSE trong Prelim
A53: 1 | B53: Ép cọc đại trà (ID 3–5) | C53: =TienDo!$F$10 -> 46218 | D53: =TienDo!$G$12 -> 46278 | E53: Máy ép, cẩu, lật đổ thiết bị; va chạm xe máy với người; điện thi công | F53: Phân luồng, rào chắn khu vực ép; kiểm định thiết bị; người điều phối tín hiệu; nền ổn định cho máy ép | G53: Cọc tiêu 50; cờ cảnh báo 150 cuộn
A54: 2 | B54: Đào đất, thi công móng (ID 14, 37, 60, 78) | C54: =TienDo!$F$21 -> 46240 | D54: =TienDo!$G$45 -> 46280 | E54: Sạt lở, hố sâu, ngập nước mùa mưa; máy đào – người | F54: Taluy/chống vách; rào chắn & biển hố sâu; bơm nước; cấm người trong bán kính làm việc của máy | G54: Biển báo hố sâu 4 cái
...

Sheet ChiPhi
A1: CHI PHÍ PHỤC VỤ THI CÔNG (PRELIM) – TỔNG HỢP & ĐỐI SOÁT
A2: Nguồn: Bảng khối lượng Prelim (sheet Prelims, Rev 00) – chưa bao gồm VAT. Cột Thành tiền lấy nguyên số liệu trong file; nhóm và tổng là công thức.
A4: STT | B4: Nội dung công việc | C4: ĐVT | D4: KL | E4: Đơn giá (VND) | F4: Thành tiền (VND) | G4: % tổng | H4: Gắn với tiến độ / ghi chú
B5: TỔNG CỘNG (chưa VAT) | F5: =F6+F11+F16+F30+F36+F42+F51+F54+F57+F61+F66 -> 1.5470112e+10 | G5: =F5/$F$5 -> 1
A6: I | B6: CÁC ĐIỀU KIỆN HỢP ĐỒNG | F6: =SUM(F7:F10) -> 374400000 | G6: =F6/$F$5 -> 0.024201506 | H6: Đầu hợp đồng; bảo lãnh theo mốc hợp đồng
A7: 1 | B7: Bảo lãnh dự thầu | C7: Lot | D7: 1 | E7: 28800000 | F7: 28800000 | G7: =F7/$F$5 -> 0.0018616543
A8: 2 | B8: Bảo lãnh tạm ứng | C8: Lot | D8: 1 | E8: 129600000 | F8: 129600000 | G8: =F8/$F$5 -> 0.0083774443
A9: 3 | B9: Bảo lãnh thực hiện hợp đồng | C9: Lot | D9: 1 | E9: 43200000 | F9: 43200000 | G9: =F9/$F$5 -> 0.0027924814
A10: 4 | B10: Bảo lãnh tiền giữ lại | C10: Lot | D10: 1 | E10: 172800000 | F10: 172800000 | G10: =F10/$F$5 -> 0.011169926
A11: II | B11: CHI PHÍ BẢO HIỂM | F11: =SUM(F12:F15) -> 7.9407262e+08 | G11: =F11/$F$5 -> 0.051329469 | H11: Đầu dự án (trước 21/06–01/07/2026)
A12: 5 | B12: Bảo hiểm vật tư, máy móc thiết bị thi công | C12: Lot | D12: 1 | E12: 21777620 | F12: 21777620 | G12: =F12/$F$5 -> 0.0014077222
A13: 6 | B13: Bảo hiểm tai nạn đối với người lao động | C13: Lot | D13: 1 | E13: 247295000 | F13: 247295000 | G13: =F13/$F$5 -> 0.01598534
A14: 7 | B14: Bảo hiểm cho rủi ro cho công trình & Bảo hiểm trách nhiệm dân sự đối với người thứ 3 | C14: Lot | D14: 1 | E14: 525000000 | F14: 525000000 | G14: =F14/$F$5 -> 0.033936406
A15: 8 | B15: Bảo hiểm cho cán bộ chủ đầu tư | C15: Lot | D15: 1 | E15: 0 | F15: 0 | G15: =F15/$F$5 -> 0 | H15: Không bao gồm
A16: III | B16: TIỆN ÍCH CỦA NHÀ THẦU, BAN QUẢN LÝ | F16: =SUM(F17:F29) -> 1.4115596e+09 | G16: =F16/$F$5 -> 0.091244308 | H16: ID 8–10 (21/06–06/07/2026) → tháo dỡ cuối dự án
A17: 9 | B17: Văn phòng, phòng họp của CĐT, tư vấn | C17: Lot | D17: 1 | E17: 0 | F17: 0 | G17: =F17/$F$5 -> 0
A18: 10 | B18: Tiện ích văn phòng CĐT, Tư vấn | C18: Lot | D18: 1 | E18: 0 | F18: 0 | G18: =F18/$F$5 -> 0
A19: 11 | B19: Văn phòng, phòng họp của nhà thầu | C19: Lot | D19: 1 | E19: 104925460 | F19: 104925460 | G19: =F19/$F$5 -> 0.006782463
A20: 12 | B20: Tiện ích của nhà thầu | C20: Lot | D20: 1 | E20: 49683333 | F20: 49683333 | G20: =F20/$F$5 -> 0.0032115691
A21: 13 | B21: Cầu rửa xe | C21: Lot | D21: 1 | E21: 0 | F21: 0 | G21: =F21/$F$5 -> 0
A22: 14 | B22: Kho vật liệu | C22: Lot | D22: 1 | E22: 25230840 | F22: 25230840 | G22: =F22/$F$5 -> 0.001630941
A23: 15 | B23: Khu vực tập kết (Nhà để xe, khu vực huấn luyện an toàn, kv hút thuốc, bãi gia công) | C23: Lot | D23: 1 | E23: 56720000 | F23: 56720000 | G23: =F23/$F$5 -> 0.0036664247
A24: 16 | B24: Hàng rào tạm bằng tole | C24: Lot | D24: 1 | E24: 0 | F24: 0 | G24: =F24/$F$5 -> 0
A25: 17 | B25: Cổng tạm | C25: Lot | D25: 1 | E25: 0 | F25: 0 | G25: =F25/$F$5 -> 0
A26: 18 | B26: Đường tạm | C26: Lot | D26: 1 | E26: 1098300000 | F26: 1098300000 | G26: =F26/$F$5 -> 0.070994962 | H26: gói thầu liên doanh nên chỉ tính đường tạm cho AZB
A27: 19 | B27: Bảng hiệu công trình | C27: Lot | D27: 1 | E27: 11700000 | F27: 11700000 | G27: =F27/$F$5 -> 0.00075629706
A28: 20 | B28: Vật tư phụ phục vụ công tác tạm | C28: Lot | D28: 1 | E28: 5000000 | F28: 5000000 | G28: =F28/$F$5 -> 0.00032320387
A29: 21 | B29: Chi phí vận chuyển thiết bị thi công công tác tạm | C29: Lot | D29: 1 | E29: 60000000 | F29: 60000000 | G29: =F29/$F$5 -> 0.0038784465
A30: IV | B30: BẢO VỆ AN NINH, AN TOÀN TRÊN CÔNG TRƯỜNG | F30: =SUM(F31:F35) -> 271371175 | G30: =F30/$F$5 -> 0.017541643 | H30: Suốt dự án (270 ngày)
A31: 22 | B31: Chòi bảo vệ | C31: Lot | D31: 1 | E31: 6000000 | F31: 6000000 | G31: =F31/$F$5 -> 0.00038784465
A32: 23 | B32: Chi phí nhân viên bảo vệ cổng (24 | C32: Lot | D32: 1 | E32: 171000000 | F32: 171000000 | G32: =F32/$F$5 -> 0.011053572
A33: 24 | B33: Y tế và sơ cấp cứu | C33: Lot | D33: 1 | E33: 4060000 | F33: 4060000 | G33: =F33/$F$5 -> 0.00026244154
A34: 25 | B34: Thiết bị bảo hộ an toàn | C34: Lot | D34: 1 | E34: 71665800 | F34: 71665800 | G34: =F34/$F$5 -> 0.0046325328
A35: 26 | B35: Biển báo chỉ dẫn an toàn | C35: Lot | D35: 1 | E35: 18645375 | F35: 18645375 | G35: =F35/$F$5 -> 0.0012052515
A36: V | B36: VỆ SINH MÔI TRƯỜNG | F36: =SUM(F37:F41) -> 9.9099167e+08 | G36: =F36/$F$5 -> 0.064058469 | H36: Suốt dự án; vệ sinh bàn giao theo ID 85 (16/02–18/03/2027)
A37: 27 | B37: Chi phí công nhật vệ sinh công trường | C37: Lot | D37: 1 | E37: 375030000 | F37: 375030000 | G37: =F37/$F$5 -> 0.02424223
A38: 28 | B38: Nhà vệ sinh tạm trên công trường | C38: Lot | D38: 1 | E38: 34906667 | F38: 34906667 | G38: =F38/$F$5 -> 0.002256394
A39: 29 | B39: Nhà vệ sinh tạm Công nhân trên công trường | C39: Lot | D39: 1 | E39: 69813333 | F39: 69813333 | G39: =F39/$F$5 -> 0.0045127879
A40: 30 | B40: Chi phí vận chuyển rác, xà bần ra khỏi công trường | C40: Lot | D40: 1 | E40: 1.6516667e+08 | F40: 1.6516667e+08 | G40: =F40/$F$5 -> 0.010676501
A41: 31 | B41: Chi phí vệ sinh bàn giao công trường | C41: Lot | D41: 1 | E41: 346075000 | F41: 346075000 | G41: =F41/$F$5 -> 0.022370556
...

Sheet RuiRo
A1: RỦI RO, SAI LỆCH DỮ LIỆU & KIẾN NGHỊ
A2: Đánh giá sơ bộ từ việc đối chiếu bảng tiến độ và bảng khối lượng Prelim – cần xác nhận với các bên liên quan trước khi chốt.
A3: # | B3: Nhóm | C3: Phát hiện | D3: Căn cứ | E3: Mức độ | F3: Kiến nghị | G3: Người phụ trách / hạn xử lý
A4: 1 | B4: Dữ liệu | C4: Hai file lệch mốc thời gian: tiến độ 21/06/2026–18/03/2027; Prelim 01/07/2026–28/03/2027 (cùng 270 ngày, lệch 10 ngày). BCH, công nhật, thiết bị tính từ 01/07 trong khi chuẩn bị mặt bằng bắt đầu 21/06. | D4: TienDo ID 1; NguonLuc mục 3 | E4: Cao | F4: Thống nhất một mốc khởi công; cập nhật lại thời gian bố trí nhân sự/thiết bị trong Prelim hoặc dịch tiến độ.
A5: 2 | B5: Tiến độ | C5: Công tác kiến trúc nhà xưởng (ID 52–56: xây tường từ 21/06, trát 01/07, sơn 21/07, hoàn thiện đến 24/08/2026) bắt đầu trước móng (25/07) và kết cấu thép (31/08). Nhiều khả năng nhập sai ngày; ID 34 cũng bắt đầu 21/06 chỉ vì nhóm này. | D5: TienDo ID 34, 52–56 | E5: Cao | F5: Xác nhận lại logic với phòng kế hoạch; nếu dời sau kết cấu thép/tôn vách (từ 29/12/2026) cần đánh giá lại mốc 08/01/2027 và 18/03/2027.
A6: 3 | B6: Tiến độ | C6: Văn phòng tạm (ID 8) ghi 24 ngày nhưng kéo dài 21/06–26/12/2026 (188 ngày); ID 7 ghi 188,88 ngày (số lẻ). | D6: TienDo ID 7–8, cột Kiểm tra | E6: Thấp | F6: Chuẩn hoá lại thành 2 dòng: lắp dựng (24 ngày) và duy trì/tháo dỡ (đến 26/12).
A7: 4 | B7: Tiến độ | C7: Dựng thép bắt đầu trước khi móng hoàn thành: nhà VP dựng từ 16/08 nhưng móng–cổ cột đến 05/09; xưởng dựng từ 31/08 nhưng ép cọc đến 03/09 và cổ cột đến 15/09. | D7: TienDo ID 14, 19, 3, 38, 40 | E7: Trung bình | F7: Chia phân khu theo trục; ghi rõ điều kiện cường độ/bảo dưỡng bê tông trước khi dựng; lập sơ đồ phân khu & trình tự.
A8: 5 | B8: Tiến độ | C8: Ép cọc xưởng đến 03/09 chạy song song đào móng xưởng từ 25/07; mốc bàn giao cọc ép (ID 2) là đầu vào của móng ba nhà. | D8: TienDo ID 2–5, 37 | E8: Cao | F8: Lập lịch bàn giao cọc theo phân khu; họp phối hợp hàng tuần với đơn vị ép cọc; mốc kiểm soát 15/07, 30/07, 03/09, 13/09.
A9: 6 | B9: Tiến độ | C9: Tiến độ tính theo ngày lịch (Số ngày = Kết thúc – Bắt đầu), chưa tách Chủ nhật, ngày lễ, mưa (đến khoảng tháng 11) và Tết Đinh Mùi (Mùng 1 = 06/02/2027). | D9: TienDo cột H–I, L | E9: Cao | F9: Lập lịch làm việc (calendar) trong MS Project: nghỉ Chủ nhật/lễ/Tết, hệ số mưa; chạy lại đường găng và trình lại ngày hoàn thành.
A10: 7 | B10: Tiến độ | C10: Chuỗi cuối dự án không có dự trữ: Hoàn thiện đường nội bộ (ID 32, 01/02–18/03/2027) và Bàn giao (ID 84–85, 16/02–18/03/2027) kết thúc đúng mốc cuối và trùng Tết; thoát nước/đường nội bộ/bó vỉa là chuỗi dẫn tới mốc này. Nhà xưởng còn dự trữ ~69 ngày, nhà VP ~104 ngày. | D10: TienDo ID 27–32, 84–85, cột Dự trữ | E10: Cao | F10: Đẩy sớm hạ tầng (thoát nước 13/09 đã có), bổ sung nhân lực hạ tầng trước Tết; thống nhất kế hoạch trực Tết.
A11: 8 | B11: Nguồn lực | C11: Prelim không bố trí: quản lý tiến độ, KS giám sát kết cấu thép, trắc đạc, chỉ huy phó, trưởng nhóm giám sát hạ tầng/M&E trong khi xưởng thép ~27.225 m² và nhiều hạng mục song song; trắc đạc công trình = 0 đồng. | D11: NguonLuc mục 1; Prelims #42 | E11: Trung bình | F11: Xác nhận ai đảm nhiệm trắc đạc/giám sát kết cấu thép (nhân sự hay thuê ngoài/CĐT).
A12: 9 | B12: HSSE | C12: Chỉ 1 an toàn viên cho 250 công nhân (250:1); không có Trưởng ban HSSE, không có y tá; bộ PPE mua 10 áo phản quang an toàn viên và 3 nón xanh HSE (không khớp 1 người). Nhiều mặt trận đồng thời (xưởng, VP, hạ tầng, cầu ống, trạm cân). | D12: HSSE mục 1; Pre_Manpower | E12: Cao | F12: Rà soát theo Luật ATVSLĐ 2015 và NĐ 39/2016/NĐ-CP; bổ sung an toàn viên/Trưởng ban HSSE trong các giai đoạn cao điểm (dựng thép, hạ tầng).
A13: 10 | B13: Biện pháp | C13: Các dòng cấp nguồn điện–nước tạm đều có KL = 0 (trạm biến áp, dây ABC, tủ DB-T1, đấu nối điện/nước tạm, đồng hồ nước D60, máy phát) – chỉ có chiếu sáng, bồn nước 7 × 2 m³, chống sét. Mốc ID 10 (kết nối điện nước tạm xong 06/07/2026). | D13: BienPhap mục 1; Pre_Diennuoctam | E13: Cao | F13: Xác nhận nguồn điện/nước tạm do CĐT/KCN cấp (điểm đấu nối, công suất cho máy hàn/đầm) hay nhà thầu; bổ sung vào Prelim nếu thiếu.
A14: 11 | B14: Biện pháp | C14: Văn phòng CĐT & tư vấn, hàng rào/cổng tạm (ghi chú: thầu AB chịu trách nhiệm), cầu rửa xe, nhà huấn luyện an toàn, bãi tập kết ngoài trời đều KL = 0. | D14: BienPhap ghi chú; Prelims #9–17 | E14: Trung bình | F14: Đối chiếu hợp đồng để phân định trách nhiệm; tránh phát sinh chi phí/bị chậm khi cần huấn luyện an toàn cho 250 công nhân.
A15: 12 | B15: Biện pháp | C15: 2 container vệ sinh 10ft cho ~250 công nhân và 1 container cho BCH. | D15: BienPhap mục 1 | E15: Trung bình | F15: Kiểm tra số lượng theo QCVN 18:2014/BXD và quy định của CĐT.
... A20: 17 | B20: Thiết bị | C20: Thiết bị nâng chỉ có 1 lot cẩu Kato/cẩu thùng (1,8 tỷ), không có cẩu tháp/vận thăng; giai đoạn 17/09–07/10/2026 có ba mặt trận dựng thép cùng lúc (xưởng, nhà đóng cont, cầu ống) và tôn mái xưởng từ 30/09. | D20: TienDo ID 40, 63, 79; NguonLuc mục 5 | E20: Trung bình | F20: Xác nhận số lượng/ca cẩu và đội dựng; lập lịch cẩu theo tuần.
B22: Số mục mức Cao | C22: =COUNTIF(E4:E20,"Cao") -> 8
